Workbook

Sheet About
A1: Nederland's Eldora acquisition: data
A2: From https://eldorarecord.org/, an independent compilation of Town of Nederland public records. Not affiliated with the Town of Nederland, POWDR, or Eldora Mountain Resort.
A3: Payments through the Oct. 20, 2026, warrant list.
A5: Sheets
A6: Summary: the headline figures on the page, with how each is calculated.
A7: Payments: every invoice charged to General Fund account 10-00-1150, "Due From" (the account used for Eldora acquisition costs), plus the amounts the Town's ledger shows were added to the account between warrant lists.
A8: Off-list postings: amounts added to the account balance between warrant lists, with what the Town's ledger for the account says about each.
A9: Running balance: the account balance after each warrant list the Board approved.
A10: Payees: totals by payee, with the evidence rating used on the page.
A11: Estimates vs paid: what the Board was told an engagement would cost, and what was paid.
A12: Commitments: amounts committed or authorized, and their status.
A13: CSAFE and funds: who owns the pooled cash and investments the Town says would pay the costs.
... A25: Corrections: corrections@eldorarecord.org

Sheet Summary
A1: Figure | B1: Amount | C1: How it is calculated | D1: Source
A2: Paid through warrant lists | B2: =SUMIF(Payments!$G$2:$G$77,"Yes",Payments!$F$2:$F$77) | C2: Sum of the invoices on Board-approved warrant lists (Payments, On warrant list = Yes). | D2: Payments
A3: Posted between warrant lists | B3: =SUM('Off-list postings'!C2:C11) | C3: Amounts added to the account between warrant lists (Town ledger). | D3: Off-list postings
A4: Already paid | B4: =B2+B3 | C4: Charged to the account through the Oct. 20, 2026, warrant list. Should equal the last running balance (next row). | D4: Payments, Off-list postings
A5: Check: last running balance | B5: ='Running balance'!B23 | C5: The account balance on the latest warrant list. | D5: Running balance
A6: Town's estimate if the sale fails | B6: 2500000 | C6: Transaction costs the Town says it would owe, paid from CSAFE investments (Sept. 30, 2026, update). | D6: https://www.nederlandco.gov/m/newsflash/home/detail/21
A7: Owed, confirmed by firms as of Oct. 16, 2026 | B7: 1673621.2 | C7: Unpaid invoices and unbilled work the firms confirmed to the Town, released Oct. 29, 2026, in response to a public records request. Firms that sent no confirmation are not included. | D7: https://eldorarecord.org/records/2026-10-29-town-cora-response.txt
A8: Itemized total if the sale fails | B8: =B4+B7 | C8: Already paid plus confirmed owed. The page's calculations use this figure in place of the Town's unitemized estimate.
A9: Paid to POWDR (the seller) | B9: =SUMIF(Payments!$B$2:$B$77,"POWDR Corp",Payments!$F$2:$F$77) | C9: Invoices on warrant lists. | D9: Payments
A10: Check: total by payee | B10: =Payees!C20 | C10: Should equal Already paid. | D10: Payees

Sheet Payments
A1: Warrant list date | B1: Payee (as listed) | C1: Payee | D1: Invoice | E1: Invoice date | F1: Amount | G1: On warrant list | H1: Days from invoice to warrant list | I1: Evidence rating | J1: Source | K1: Source URL
A2: 45937 | B2: JVA | C2: JVA | D2: 25772 | E2: 45900 | F2: 7547.4 | G2: Yes | H2: 37 | I2: Account coding only | J2: Warrant list p. 10 | K2: https://nederlandco.civicweb.net/document/124842/
A3: 45937 | B3: Widner Juran LLP | C3: Widner Juran LLP | D3: 46.0309 | E3: 45900 | F3: 29508.5 | G3: Yes | H3: 37 | I3: Account coding only | J3: Warrant list p. 11 | K3: https://nederlandco.civicweb.net/document/124842/
A4: 45937 | B4: DiNatale Water Consultants | C4: DiNatale Water Consultants | D4: 4884 | E4: 45900 | F4: 9782.4 | G4: Yes | H4: 37 | I4: Account coding only | J4: Warrant list p. 12 | K4: https://nederlandco.civicweb.net/document/124842/
A5: 45937 | B5: Sno.engineering | C5: SE Group | D5: 6443 | E5: 45904 | F5: 20653.74 | G5: Yes | H5: 33 | I5: Named in Board documents | J5: Warrant list p. 12 | K5: https://nederlandco.civicweb.net/document/124842/
A6: 45951 | B6: Widner Juran LLP | C6: Widner Juran LLP | D6: 46.0313 | E6: 45930 | F6: 27816 | G6: Yes | H6: 21 | I6: Account coding only | J6: Warrant list p. 2 | K6: https://nederlandco.civicweb.net/document/125193/
A7: 45951 | B7: DiNatale Water Consultants | C7: DiNatale Water Consultants | D7: 4924 | E7: 45930 | F7: 7965 | G7: Yes | H7: 21 | I7: Account coding only | J7: Warrant list p. 3 | K7: https://nederlandco.civicweb.net/document/125193/
A8: 45951 | B8: Sno.engineering | C8: SE Group | D8: 6539 | E8: 45931 | F8: 23388 | G8: Yes | H8: 20 | I8: Named in Board documents | J8: Warrant list p. 3 | K8: https://nederlandco.civicweb.net/document/125193/
A9: 45951 | B9: Dickinson Wright PLLC | C9: Dickinson Wright | D9: 2080024 | E9: 45923 | F9: 40469.18 | G9: Yes | H9: 28 | I9: Named in Board documents | J9: Warrant list p. 3 | K9: https://nederlandco.civicweb.net/document/125193/
A10: 45966 | B10: JVA | C10: JVA | D10: 26304 | E10: 45930 | F10: 13191.3 | G10: Yes | H10: 36 | I10: Account coding only | J10: Warrant list p. 1 | K10: https://nederlandco.civicweb.net/document/125512/
B11: Widner Juran LLP | C11: Widner Juran LLP | D11: 46.0292 | E11: 45688 | F11: 6440 | G11: No | I11: Account coding only | J11: Moved into this account from Legal (10-12-5100) by a Town ledger entry dated Sept 30, 2025; first paid on the Feb. 18, 2025, warrant list, p. 6 (https://nederlandco.civicweb.net/document/119043/); first in the account balance on the Nov. 5, 2025, warrant list | K11: https://eldorarecord.org/records/2026-09-25-eldora-reimbursable-expenses.xls
B12: Widner Juran LLP | C12: Widner Juran LLP | D12: 46.0294 | E12: 45716 | F12: 1505 | G12: No | I12: Account coding only | J12: Moved into this account from Legal (10-12-5100) by a Town ledger entry dated Sept 30, 2025; first paid on the April 15, 2025, warrant list, p. 1 (https://nederlandco.civicweb.net/document/120586/); first in the account balance on the Nov. 5, 2025, warrant list | K12: https://eldorarecord.org/records/2026-09-25-eldora-reimbursable-expenses.xls
B13: Widner Juran LLP | C13: Widner Juran LLP | D13: 46.0297 | E13: 45747 | F13: 1295 | G13: No | I13: Account coding only | J13: Moved into this account from Legal (10-12-5100) by a Town ledger entry dated Sept 30, 2025; first paid on the May 6, 2025, warrant list, p. 2 (https://nederlandco.civicweb.net/document/120975/); first in the account balance on the Nov. 5, 2025, warrant list | K13: https://eldorarecord.org/records/2026-09-25-eldora-reimbursable-expenses.xls
B14: Widner Juran LLP | C14: Widner Juran LLP | D14: 46.0301 | E14: 45777 | F14: 2747.5 | G14: No | I14: Account coding only | J14: Moved into this account from Legal (10-12-5100) by a Town ledger entry dated Sept 30, 2025; first paid on the May 20, 2025, warrant list, p. 2 (https://nederlandco.civicweb.net/document/121504/); first in the account balance on the Nov. 5, 2025, warrant list | K14: https://eldorarecord.org/records/2026-09-25-eldora-reimbursable-expenses.xls
B15: Widner Juran LLP | C15: Widner Juran LLP | D15: 46.0303 | E15: 45808 | F15: 9954 | G15: No | I15: Account coding only | J15: Moved into this account from Legal (10-12-5100) by a Town ledger entry dated Sept 30, 2025; first paid on the June 17, 2025, warrant list, p. 2 (https://nederlandco.civicweb.net/document/122041/); first in the account balance on the Nov. 5, 2025, warrant list | K15: https://eldorarecord.org/records/2026-09-25-eldora-reimbursable-expenses.xls
B16: Widner Juran LLP | C16: Widner Juran LLP | D16: 46.0304 | E16: 45838 | F16: 5162.5 | G16: No | I16: Account coding only | J16: Moved into this account from Legal (10-12-5100) by a Town ledger entry dated Sept 30, 2025; first paid on the Aug. 5, 2025, warrant list, p. 2 (https://nederlandco.civicweb.net/document/123021/); first in the account balance on the Nov. 5, 2025, warrant list | K16: https://eldorarecord.org/records/2026-09-25-eldora-reimbursable-expenses.xls
B17: Widner Juran LLP | C17: Widner Juran LLP | D17: 46.0307 | E17: 45869 | F17: 19106.5 | G17: No | I17: Account coding only | J17: Moved into this account from Legal (10-12-5100) by a Town ledger entry dated Sept 30, 2025; first paid on the Sept. 2, 2025, warrant list, p. 2 (https://nederlandco.civicweb.net/document/123789/); first in the account balance on the Nov. 5, 2025, warrant list | K17: https://eldorarecord.org/records/2026-09-25-eldora-reimbursable-expenses.xls
B18: Dickinson Wright PLLC | C18: Dickinson Wright | D18: 2070334 | E18: 45889 | F18: 9680 | G18: No | I18: Named in Board documents | J18: Moved into this account from Legal (10-12-5100) by a Town ledger entry dated Sept 30, 2025; first paid on the Oct. 7, 2025, warrant list, p. 3 (https://nederlandco.civicweb.net/document/124842/); first in the account balance on the Nov. 5, 2025, warrant list | K18: https://eldorarecord.org/records/2026-09-25-eldora-reimbursable-expenses.xls
A19: 45979 | B19: JVA | C19: JVA | D19: 26812 | E19: 45961 | F19: 1811.7 | G19: Yes | H19: 18 | I19: Account coding only | J19: Warrant list p. 2 | K19: https://nederlandco.civicweb.net/document/125911/
A20: 45979 | B20: Sno.engineering | C20: SE Group | D20: 6714 | E20: 45967 | F20: 32432 | G20: Yes | H20: 12 | I20: Named in Board documents | J20: Warrant list p. 3 | K20: https://nederlandco.civicweb.net/document/125911/
A21: 45979 | B21: Susan N. Fattor | C21: Bolder HR Solutions | D21: 0001 | E21: 45962 | F21: 3600 | G21: Yes | H21: 17 | I21: No other record | J21: Warrant list p. 4 | K21: https://nederlandco.civicweb.net/document/125911/
A22: 45979 | B22: Semple | C22: Semple, Farrington, Everall & Case | D22: 61416 | E22: 45900 | F22: 360 | G22: Yes | H22: 79 | I22: No other record | J22: Warrant list p. 4 | K22: https://nederlandco.civicweb.net/document/125911/
A23: 45993 | B23: Widner Juran LLP | C23: Widner Juran LLP | D23: 46.0315 | E23: 45961 | F23: 31381 | G23: Yes | H23: 32 | I23: Account coding only | J23: Warrant list p. 2 | K23: https://nederlandco.civicweb.net/document/126169/
A24: 45993 | B24: Farnsworth Group | C24: Farnsworth Group | D24: 264460 | E24: 45946 | F24: 24814 | G24: Yes | H24: 47 | I24: No other record | J24: Warrant list p. 3 | K24: https://nederlandco.civicweb.net/document/126169/
A25: 45993 | B25: Farnsworth Group | C25: Farnsworth Group | D25: 265418 | E25: 45982 | F25: 33956 | G25: Yes | H25: 11 | I25: No other record | J25: Warrant list p. 3 | K25: https://nederlandco.civicweb.net/document/126169/
A26: 46007 | B26: BBA Water Consultants | C26: BBA Water Consultants | D26: 57724 | E26: 45976 | F26: 6274 | G26: Yes | H26: 31 | I26: Named in Board documents | J26: Warrant list p. 4 | K26: https://nederlandco.civicweb.net/document/126508/
A27: 46042 | B27: JVA | C27: JVA | D27: 27216 | E27: 45991 | F27: 1733.4 | G27: Yes | H27: 51 | I27: Account coding only | J27: Warrant list p. 1 | K27: https://nederlandco.civicweb.net/document/127156/
A28: 46042 | B28: Widner Juran LLP | C28: Widner Juran LLP | D28: 46.0319 | E28: 45991 | F28: 19737 | G28: Yes | H28: 51 | I28: Account coding only | J28: Warrant list p. 2 | K28: https://nederlandco.civicweb.net/document/127156/
A29: 46042 | B29: Sno.engineering | C29: SE Group | D29: 6886 | E29: 45996 | F29: 10378 | G29: Yes | H29: 46 | I29: Named in Board documents | J29: Warrant list p. 2 | K29: https://nederlandco.civicweb.net/document/127156/
A30: 46042 | B30: Professional Management Systems | C30: Professional Management Solutions | D30: 85157 | E30: 45987 | F30: 639.38 | G30: Yes | H30: 55 | I30: No other record | J30: Warrant list p. 3 | K30: https://nederlandco.civicweb.net/document/127156/
... A44: 46084 | B44: POWDR Corp | C44: POWDR Corp | D44: INV3313 | E44: 46049 | F44: 124000 | G44: Yes | H44: 35 | I44: Named in Board documents | J44: Warrant list p. 3 | K44: https://nederlandco.civicweb.net/document/128049/
B45: POWDR Corp | C45: POWDR Corp | D45: 2026-01-06 | E45: 46028 | F45: 50000 | G45: No | I45: Named in Board documents | J45: In the Town ledger (invoice dated Jan 6, 2026); on no warrant list. Purpose not stated. A letter of the same date provides for a $50,000 advance to POWDR toward Ikon negotiation costs; first in the account balance on the March 3, 2026, warrant list | K45: https://eldorarecord.org/records/2026-09-25-eldora-reimbursable-expenses.xls
A46: 46112 | B46: Widner Juran LLP | C46: Widner Juran LLP | D46: 46.0326 | E46: 46081 | F46: 23203 | G46: Yes | H46: 31 | I46: Account coding only | J46: Warrant list p. 2 | K46: https://nederlandco.civicweb.net/document/128662/
A47: 46112 | B47: Sno.engineering | C47: SE Group | D47: 7242 | E47: 46085 | F47: 13033.2 | G47: Yes | H47: 27 | I47: Named in Board documents | J47: Warrant list p. 2 | K47: https://nederlandco.civicweb.net/document/128662/
A48: 46112 | B48: Farnsworth Group | C48: Farnsworth Group | D48: 266639 | E48: 46038 | F48: 6530 | G48: Yes | H48: 74 | I48: No other record | J48: Warrant list p. 3 | K48: https://nederlandco.civicweb.net/document/128662/
A49: 46112 | B49: BBA Water Consultants | C49: BBA Water Consultants | D49: 58104 | E49: 46068 | F49: 3561 | G49: Yes | H49: 44 | I49: Named in Board documents | J49: Warrant list p. 3 | K49: https://nederlandco.civicweb.net/document/128662/
A50: 46133 | B50: Datasite LLC | C50: Datasite | D50: INV-902223 | E50: 46086 | F50: 200 | G50: Yes | H50: 47 | I50: No other record | J50: Warrant list p. 3 | K50: https://nederlandco.civicweb.net/document/128980/
A51: 46147 | B51: Widner Juran LLP | C51: Widner Juran LLP | D51: 46.0330 | E51: 46112 | F51: 33367 | G51: Yes | H51: 35 | I51: Account coding only | J51: Warrant list p. 2 | K51: https://nederlandco.civicweb.net/document/129316/
A52: 46147 | B52: Datasite LLC | C52: Datasite | D52: INV-913882 | E52: 46117 | F52: 200 | G52: Yes | H52: 30 | I52: No other record | J52: Warrant list p. 4 | K52: https://nederlandco.civicweb.net/document/129316/
A53: 46147 | B53: Sno.engineering | C53: SE Group | D53: 7440 | E53: 46112 | F53: 6081.25 | G53: Yes | H53: 35 | I53: Named in Board documents | J53: Warrant list p. 12 | K53: https://nederlandco.civicweb.net/document/129316/
...

Sheet Off-list postings
A1: After list of | B1: Before list of | C1: Amount | D1: Attributed to | E1: What is known | F1: Source | G1: Source URL
A2: 45951 | B2: 45966 | C2: 6440 | D2: Widner Juran LLP | E2: Moved into this account from Legal (10-12-5100) by a Town ledger entry dated Sept 30, 2025. Invoice 46.0292 first paid on the Feb. 18, 2025, warrant list | F2: Town ledger | G2: https://eldorarecord.org/records/2026-09-25-eldora-reimbursable-expenses.xls
A3: 45951 | B3: 45966 | C3: 1505 | D3: Widner Juran LLP | E3: Moved into this account from Legal (10-12-5100) by a Town ledger entry dated Sept 30, 2025. Invoice 46.0294 first paid on the April 15, 2025, warrant list | F3: Town ledger | G3: https://eldorarecord.org/records/2026-09-25-eldora-reimbursable-expenses.xls
A4: 45951 | B4: 45966 | C4: 1295 | D4: Widner Juran LLP | E4: Moved into this account from Legal (10-12-5100) by a Town ledger entry dated Sept 30, 2025. Invoice 46.0297 first paid on the May 6, 2025, warrant list | F4: Town ledger | G4: https://eldorarecord.org/records/2026-09-25-eldora-reimbursable-expenses.xls
A5: 45951 | B5: 45966 | C5: 2747.5 | D5: Widner Juran LLP | E5: Moved into this account from Legal (10-12-5100) by a Town ledger entry dated Sept 30, 2025. Invoice 46.0301 first paid on the May 20, 2025, warrant list | F5: Town ledger | G5: https://eldorarecord.org/records/2026-09-25-eldora-reimbursable-expenses.xls
A6: 45951 | B6: 45966 | C6: 9954 | D6: Widner Juran LLP | E6: Moved into this account from Legal (10-12-5100) by a Town ledger entry dated Sept 30, 2025. Invoice 46.0303 first paid on the June 17, 2025, warrant list | F6: Town ledger | G6: https://eldorarecord.org/records/2026-09-25-eldora-reimbursable-expenses.xls
A7: 45951 | B7: 45966 | C7: 5162.5 | D7: Widner Juran LLP | E7: Moved into this account from Legal (10-12-5100) by a Town ledger entry dated Sept 30, 2025. Invoice 46.0304 first paid on the Aug. 5, 2025, warrant list | F7: Town ledger | G7: https://eldorarecord.org/records/2026-09-25-eldora-reimbursable-expenses.xls
A8: 45951 | B8: 45966 | C8: 19106.5 | D8: Widner Juran LLP | E8: Moved into this account from Legal (10-12-5100) by a Town ledger entry dated Sept 30, 2025. Invoice 46.0307 first paid on the Sept. 2, 2025, warrant list | F8: Town ledger | G8: https://eldorarecord.org/records/2026-09-25-eldora-reimbursable-expenses.xls
A9: 45951 | B9: 45966 | C9: 9680 | D9: Dickinson Wright | E9: Moved into this account from Legal (10-12-5100) by a Town ledger entry dated Sept 30, 2025. Invoice 2070334 first paid on the Oct. 7, 2025, warrant list | F9: Town ledger | G9: https://eldorarecord.org/records/2026-09-25-eldora-reimbursable-expenses.xls
A10: 46070 | B10: 46084 | C10: 50000 | D10: POWDR Corp | E10: In the Town ledger (invoice dated Jan 6, 2026); on no warrant list. Purpose not stated. A letter of the same date provides for a $50,000 advance to POWDR toward Ikon negotiation costs | F10: Town ledger | G10: https://eldorarecord.org/records/2026-09-25-eldora-reimbursable-expenses.xls
A11: 46175 | B11: 46189 | C11: 852.5 | D11: Plante Moran | E11: Part of a $1,550 invoice. Moved into this account from Professional Services (10-12-5133) by a Town ledger entry dated May 11, 2026. Invoice 10693173 first paid on the June 2, 2026, warrant list | F11: Town ledger | G11: https://eldorarecord.org/records/2026-09-25-eldora-reimbursable-expenses.xls

Sheet Running balance
A1: Warrant list date | B1: Balance after list | C1: Change since previous list | D1: Invoices on this list | E1: Not on the list | F1: Source | G1: Source URL
A2: 45937 | B2: 67492.04 | C2: =B2 | D2: =SUMIFS(Payments!$F$2:$F$77,Payments!$A$2:$A$77,A2,Payments!$G$2:$G$77,"Yes") | E2: =C2-D2 | F2: Warrant list | G2: https://nederlandco.civicweb.net/document/124842/
A3: 45951 | B3: 167130.22 | C3: =B3-B2 | D3: =SUMIFS(Payments!$F$2:$F$77,Payments!$A$2:$A$77,A3,Payments!$G$2:$G$77,"Yes") | E3: =C3-D3 | F3: Warrant list | G3: https://nederlandco.civicweb.net/document/125193/
A4: 45966 | B4: 236212.02 | C4: =B4-B3 | D4: =SUMIFS(Payments!$F$2:$F$77,Payments!$A$2:$A$77,A4,Payments!$G$2:$G$77,"Yes") | E4: =C4-D4 | F4: Warrant list | G4: https://nederlandco.civicweb.net/document/125512/
A5: 45979 | B5: 274415.72 | C5: =B5-B4 | D5: =SUMIFS(Payments!$F$2:$F$77,Payments!$A$2:$A$77,A5,Payments!$G$2:$G$77,"Yes") | E5: =C5-D5 | F5: Warrant list | G5: https://nederlandco.civicweb.net/document/125911/
A6: 45993 | B6: 364566.72 | C6: =B6-B5 | D6: =SUMIFS(Payments!$F$2:$F$77,Payments!$A$2:$A$77,A6,Payments!$G$2:$G$77,"Yes") | E6: =C6-D6 | F6: Warrant list | G6: https://nederlandco.civicweb.net/document/126169/
A7: 46007 | B7: 370840.72 | C7: =B7-B6 | D7: =SUMIFS(Payments!$F$2:$F$77,Payments!$A$2:$A$77,A7,Payments!$G$2:$G$77,"Yes") | E7: =C7-D7 | F7: Warrant list | G7: https://nederlandco.civicweb.net/document/126508/
A8: 46042 | B8: 469493 | C8: =B8-B7 | D8: =SUMIFS(Payments!$F$2:$F$77,Payments!$A$2:$A$77,A8,Payments!$G$2:$G$77,"Yes") | E8: =C8-D8 | F8: Warrant list | G8: https://nederlandco.civicweb.net/document/127156/
A9: 46056 | B9: 497805 | C9: =B9-B8 | D9: =SUMIFS(Payments!$F$2:$F$77,Payments!$A$2:$A$77,A9,Payments!$G$2:$G$77,"Yes") | E9: =C9-D9 | F9: Warrant list | G9: https://nederlandco.civicweb.net/document/127394/
A10: 46070 | B10: 536294.79 | C10: =B10-B9 | D10: =SUMIFS(Payments!$F$2:$F$77,Payments!$A$2:$A$77,A10,Payments!$G$2:$G$77,"Yes") | E10: =C10-D10 | F10: Warrant list | G10: https://nederlandco.civicweb.net/document/127711/
A11: 46084 | B11: 710294.79 | C11: =B11-B10 | D11: =SUMIFS(Payments!$F$2:$F$77,Payments!$A$2:$A$77,A11,Payments!$G$2:$G$77,"Yes") | E11: =C11-D11 | F11: Warrant list | G11: https://nederlandco.civicweb.net/document/128049/
A12: 46112 | B12: 756621.99 | C12: =B12-B11 | D12: =SUMIFS(Payments!$F$2:$F$77,Payments!$A$2:$A$77,A12,Payments!$G$2:$G$77,"Yes") | E12: =C12-D12 | F12: Warrant list | G12: https://nederlandco.civicweb.net/document/128662/
A13: 46133 | B13: 756821.99 | C13: =B13-B12 | D13: =SUMIFS(Payments!$F$2:$F$77,Payments!$A$2:$A$77,A13,Payments!$G$2:$G$77,"Yes") | E13: =C13-D13 | F13: Warrant list | G13: https://nederlandco.civicweb.net/document/128980/
A14: 46147 | B14: 796470.24 | C14: =B14-B13 | D14: =SUMIFS(Payments!$F$2:$F$77,Payments!$A$2:$A$77,A14,Payments!$G$2:$G$77,"Yes") | E14: =C14-D14 | F14: Warrant list | G14: https://nederlandco.civicweb.net/document/129316/
... A23: 46315 | B23: 1195949.4 | C23: =B23-B22 | D23: =SUMIFS(Payments!$F$2:$F$77,Payments!$A$2:$A$77,A23,Payments!$G$2:$G$77,"Yes") | E23: =C23-D23 | F23: Warrant list | G23: https://nederlandco.civicweb.net/document/132740/

Sheet Payees
A1: Payee | B1: Payee (as listed) | C1: Total paid | D1: Invoices | E1: First invoice date | F1: Last invoice date | G1: Evidence rating | H1: Note
A2: Widner Juran LLP | B2: Widner Juran LLP | C2: =SUMIF(Payments!$B$2:$B$77,B2,Payments!$F$2:$F$77) | D2: =COUNTIF(Payments!$B$2:$B$77,B2) | E2: 45688 | F2: 46265 | G2: Account coding only | H2: Town Attorney; includes $46,211 in January to July 2025 invoices moved into this account from the Legal budget · Standing appointment
A3: POWDR Corp | B3: POWDR Corp | C3: =SUMIF(Payments!$B$2:$B$77,B3,Payments!$F$2:$F$77) | D3: =COUNTIF(Payments!$B$2:$B$77,B3) | E3: 46028 | F3: 46133 | G3: Named in Board documents | H3: The seller; the records searched don't state the purpose of its three invoices, one of which ($50,000) is on no warrant list. A Jan. 6, 2026, letter provides for a $50,000 advance to POWDR toward Ikon negotiation costs · Purchase agreement
A4: Plante Moran | B4: P&M Holding Group | C4: =SUMIF(Payments!$B$2:$B$77,B4,Payments!$F$2:$F$77) | D4: =COUNTIF(Payments!$B$2:$B$77,B4) | E4: 45995 | F4: 46153 | G4: Named in Board documents | H4: Financial due diligence ("quality of earnings") on the resort, then HR and finance transition planning; since July 2026 also signs the Town's Treasurer reports; includes $853 moved into this account from Professional Services · Due diligence engagement letter of Aug. 12, 2025 (released October 2026); Res. 2025-22 covers HR and finance consultants (no firm named); then Res. 2026-12
A5: Hogan Lovells | B5: Hogan Lovells US LLP | C5: =SUMIF(Payments!$B$2:$B$77,B5,Payments!$F$2:$F$77) | D5: =COUNTIF(Payments!$B$2:$B$77,B5) | E5: 46197 | F5: 46230 | G5: No other record | H5: Role not stated in the records searched · appears in the records searched only on the July 21 and Aug. 18, 2026, warrant lists and in the Town's ledger for the account
A6: SE Group | B6: Sno.engineering | C6: =SUMIF(Payments!$B$2:$B$77,B6,Payments!$F$2:$F$77) | D6: =COUNTIF(Payments!$B$2:$B$77,B6) | E6: 45904 | F6: 46177 | G6: Named in Board documents | H6: Operations, market, and financial review of the resort · Res. 2025-15
A7: Farnsworth Group | B7: Farnsworth Group | C7: =SUMIF(Payments!$B$2:$B$77,B7,Payments!$F$2:$F$77) | D7: =COUNTIF(Payments!$B$2:$B$77,B7) | E7: 45946 | F7: 46038 | G7: No other record | H7: Land survey of two resort parcels, including the "Cabin Parcel," for a fixed fee of $65,300 · Agreement of August 2025 (released October 2026); not in the Board documents searched
A8: Dickinson Wright | B8: Dickinson Wright PLLC | C8: =SUMIF(Payments!$B$2:$B$77,B8,Payments!$F$2:$F$77) | D8: =COUNTIF(Payments!$B$2:$B$77,B8) | E8: 45889 | F8: 45923 | G8: Named in Board documents | H8: Water-rights due diligence (its other water-law work is billed to the Water Fund); includes a $9,680 invoice moved into this account from the Legal budget · Engagement approved July 15, 2025
A9: Kline Alvarado Veio | B9: Kline Veio | C9: =SUMIF(Payments!$B$2:$B$77,B9,Payments!$F$2:$F$77) | D9: =COUNTIF(Payments!$B$2:$B$77,B9) | E9: 46189 | F9: 46189 | G9: Named in Board documents | H9: Bond counsel; fee estimate $200,000 to $250,000, payable at closing, or accrued time billed hourly if no bonds are issued · Res. 2025-16 (named); engagement letter of Aug. 1, 2025 (released October 2026)
A10: Partner Engineering and Science | B10: Partner Assessment Corporation | C10: =SUMIF(Payments!$B$2:$B$77,B10,Payments!$F$2:$F$77) | D10: =COUNTIF(Payments!$B$2:$B$77,B10) | E10: 45930 | F10: 46022 | G10: No other record | H10: Role not stated in the records searched; the November 2025 Eldora memo reports a property condition assessment and an environmental site assessment without naming who did them · no engagement record in the Board documents searched
A11: JVA | B11: JVA | C11: =SUMIF(Payments!$B$2:$B$77,B11,Payments!$F$2:$F$77) | D11: =COUNTIF(Payments!$B$2:$B$77,B11) | E11: 45900 | F11: 45991 | G11: Account coding only | H11: The Town's on-call engineers · Regular Town vendor
A12: DiNatale Water Consultants | B12: DiNatale Water Consultants | C12: =SUMIF(Payments!$B$2:$B$77,B12,Payments!$F$2:$F$77) | D12: =COUNTIF(Payments!$B$2:$B$77,B12) | E12: 45900 | F12: 45930 | G12: Account coding only | H12: The Town's water engineers · Regular Town vendor
A13: BBA Water Consultants | B13: BBA Water Consultants | C13: =SUMIF(Payments!$B$2:$B$77,B13,Payments!$F$2:$F$77) | D13: =COUNTIF(Payments!$B$2:$B$77,B13) | E13: 45976 | F13: 46068 | G13: Named in Board documents | H13: Eldora's own water consultant under the purchase agreement; engaged by the Town, with a conflict waiver, to update Eldora's 2016 water sufficiency letter for the Forest Service permit transfer · Purchase agreement; engagement letter of Oct. 8, 2025 (released October 2026)
... A19: Professional Management Solutions | B19: Professional Management Systems | C19: =SUMIF(Payments!$B$2:$B$77,B19,Payments!$F$2:$F$77) | D19: =COUNTIF(Payments!$B$2:$B$77,B19) | E19: 45987 | F19: 45987 | G19: No other record | H19: Role not stated in the records searched · no engagement record in the Board documents searched
A20: Total | C20: =SUM(C2:C19) | D20: =SUM(D2:D19)

Sheet Estimates vs paid
A1: Engagement | B1: Approved or disclosed | C1: Estimate (high end) | D1: Estimate incl. expenses | E1: Paid | F1: Notes | G1: Source | H1: Source URL
A2: SE Group due diligence | B2: 45853 | C2: 69000 | D2: 75900 | E2: 134230.69 | F2: "We anticipate our professional fees will not exceed $69,000," plus expenses of "typically 10%." Res. 2025-15 approved the agreement "substantially in the form of the proposal." | G2: Proposal pp. 4–5 | H2: https://nederlandco.civicweb.net/document/122625/
A3: Plante Moran transition planning | B3: 46133 | C3: 110000 | D3: 110000 | E3: 161656.14 | F3: Estimated $90,000 to $110,000 over four to five weeks. Its Eldora acquisition charges are on invoices dated Dec. 4, 2025, to April 17, 2026. Res. 2025-22 (Oct. 7, 2025) authorized the Town Manager to engage HR and finance consultants; it names no firm or estimate. | G3: Engagement letter p. 3 | H3: https://nederlandco.civicweb.net/document/128983/
A4: Dickinson Wright water-rights due diligence | B4: 45853 | E4: 50149.18 | F4: Hourly rate only ($385); the engagement letter gives no estimate. | G4: Memo | H4: https://nederlandco.civicweb.net/document/122662/
A5: Town Attorney, Widner Juran | B5: 45853 | E5: 287307 | F5: A July 2025 rate memo set a $290 hourly "pass-through" rate from January 2026. No estimate of hours. | G5: Memo | H5: https://nederlandco.civicweb.net/document/122661/
A6: Hogan Lovells (other legal counsel, Res. 2025-16) | B6: 45874 | E6: 148794.5 | F6: The Town Manager "will keep the Board of Trustees informed about all necessary legal engagements." Hogan Lovells appears in no Board document searched except the warrant lists. A briefing in executive session would not appear in public records. | G6: Res. 2025-16 | H6: https://nederlandco.civicweb.net/document/123040/
A7: Stifel (financial advisor) | B7: 46210 | C7: 325000 | D7: 325000 | E7: 0 | F7: Paid only if the bonds are sold. | G7: Memo | H7: https://nederlandco.civicweb.net/document/130471/

Sheet Commitments
A1: Item | B1: Amount | C1: Qualifier | D1: Status | E1: Notes | F1: Source | G1: Source URL
A2: Purchase price for Eldora's assets | B2: 120000000 | D2: Expired | E2: No deposit required. The Town said Sept. 30, 2026, that the agreement "has expired." | F2: Ord. 882, APA §2.5 | G2: https://nederlandco.civicweb.net/document/126803/
A3: Series 2026 revenue bonds (up to 40 years, at most 9% interest) | B3: 225000000 | C3: up to | D3: Lapsed | E3: Had to be sold within 180 days (about July 19, 2026). None were sold. | F3: Ord. 885 §5(c) | G3: https://nederlandco.civicweb.net/document/127180/
A4: Expected maximum bond amount (intent to repay early costs from bonds) | B4: 180000000 | D4: Declared | F4: Res. 2025-17 | G4: https://nederlandco.civicweb.net/document/123060/
A5: Transaction costs owed if the sale does not close | B5: 2500000 | C5: about | D5: Town estimate | E5: To be paid from CSAFE investments; reimbursable from bond proceeds if the deal closes. Not itemized; paid plus confirmed owed is about $2.9 million (Summary). | F5: Sept. 30, 2026, update | G5: https://www.nederlandco.gov/m/newsflash/home/detail/21
A6: Planned philanthropic fundraising for capital projects | B6: 20000000 | C6: about | D6: Planned | E6: Jolly Jug, Corona lift, mountaintop lodge, summer operations. | F6: Sept. 30, 2026, update | G6: https://www.nederlandco.gov/m/newsflash/home/detail/21
A7: Stifel financial-advisor fee | B7: 325000 | D7: If bonds sell | E7: Paid from bond proceeds. | F7: July 7, 2026, memo | G7: https://nederlandco.civicweb.net/document/130471/
A8: Emergency spending beyond the budget (Res. 2026-13) | C8: no dollar limit | D8: Lapsed | E8: Authority ran 120 days from April 21, 2026, or until a supplemental budget. | F8: Res. 2026-13 | G8: https://nederlandco.civicweb.net/document/129046/
A9: Mountain Recreation Enterprise in the 2025 and 2026 budgets | B9: 0 | D9: Not budgeted | F9: April 21, 2026, memo | G9: https://nederlandco.civicweb.net/document/129045/

Sheet CSAFE and funds
A1: Fund (Dec. 31, 2025) | B1: Cash and investments | C1: Amount it is owed by (+) or owes (-) other funds | D1: Can it pay Eldora acquisition costs? | E1: Why
A2: Water and Sewer (utility funds) | B2: 4150620 | C2: -1118188 | D2: Generally no | E2: Utility rate revenue funds the utilities; the audit classifies $436,250 of the utilities' net position as restricted.
A3: Downtown Development Authority | B3: 1695802 | C3: 0 | D3: No | E3: A separate authority's money for downtown purposes.
A4: Community Center | B4: 964480 | C4: -158347 | D4: No | E4: Restricted to the community center.
A5: Streets; Conservation Trust (parks) | B5: 343690 | C5: -179698 | D5: No | E5: Restricted to roads, parks, and trails.
A6: General Fund | B6: 0 | C6: 1456233 | D6: Yes, if the Board appropriates it | E6: Its cash was negative: the audit says its "negative cash balance of $757,482" is "reported as accounts payable." $147,000 of its fund balance is restricted as the TABOR emergency reserve.
A7: Total | B7: =SUM(B2:B6) | C7: =SUM(C2:C6) | E7: Cash total equals the audit's deposits and investments ($7,154,592); amounts owed and due net to zero.
A8: If the other funds paid the General Fund what they owed, and that covered its negative cash balance, the General Fund would hold about $698,751 of the pooled cash and investments ($1,456,233 - $757,482; this workbook's calculation, not an audit figure). The audit expects the amounts owed to clear after year end but doesn't say how the negative balance would be settled. Eldora acquisition costs paid since year end are on the Payments sheet.
A10: Key audited figures | B10: Amount | C10: Date | D10: Source
A11: CSAFE investment balance | B11: 2700831 | C11: Dec. 31, 2024 | D11: 2025 audit
A12: CSAFE investment balance | B12: 2821014 | C12: Dec. 31, 2025 | D12: 2025 audit
A13: General Fund fund balance | B13: 1030078 | C13: Dec. 31, 2025 | D13: 2025 audit
A14: General Fund unassigned fund balance | B14: 872173 | C14: Dec. 31, 2025 | D14: 2025 audit
A15: General Fund negative cash balance (reported as accounts payable) | B15: -757482 | C15: Dec. 31, 2025 | D15: 2025 audit
A16: Owed to the General Fund by other funds | B16: 1456233 | C16: Dec. 31, 2025 | D16: 2025 audit
A17: General Fund TABOR emergency reserve | B17: 147000 | C17: Dec. 31, 2025 | D17: 2025 audit
A18: General Fund "other receivables" | B18: 6431 | C18: Dec. 31, 2024 | D18: 2025 audit
A19: General Fund "other receivables" (not itemized in the audit) | B19: 520055 | C19: Dec. 31, 2025 | D19: 2025 audit
A20: General Fund balance projected in the adopted 2026 budget | B20: 583730 | C20: Dec. 31, 2026 | D20: 2026 budget summary

Sheet For scale
A1: Project | B1: Total | C1: Grant share | D1: Town share | E1: Note | F1: Source | G1: Source URL
A2: Eldora, if the sale fails (paid plus confirmed owed) | B2: 2869570.5 | C2: 0 | D2: =B2-C2 | E2: no grants | F2: Summary sheet
A3: Eldora, paid so far | B3: 1195949.4 | C3: 0 | D3: =B3-C3 | E3: no grants | F3: Summary sheet
A4: Street equipment lease-purchase, 2023 | B4: 511000 | C4: 0 | D4: =B4-C4 | E4: repaid over 5 years | F4: Board packet | G4: https://nederlandco.civicweb.net/document/44830/
A5: Comprehensive Plan, 2023–2025 | B5: 205188 | C5: 100000 | D5: =B5-C5 | E5: state grant | F5: Board packet | G5: https://nederlandco.civicweb.net/document/119355/
A6: Crosswalk improvements, 2026 | B6: 360000 | C6: 300000 | D6: =B6-C6 | E6: federal grant | F6: Board packet | G6: https://nederlandco.civicweb.net/document/129318/
A7: Emergency sirens, proposed 2026 | B7: 260000 | C7: 195000 | D7: =B7-C7 | E7: federal grant applied for | F7: Board packet | G7: https://nederlandco.civicweb.net/document/130735/
A8: Shared housing coordinator, 3 years | B8: 200000 | C8: 160000 | D8: =B8-C8 | E8: state grant | F8: Board packet | G8: https://nederlandco.civicweb.net/document/122222/
A10: Town budgets | B10: Amount | E10: Note | F10: Source | G10: Source URL
A11: All funds, adopted 2026 budget | B11: 9400000 | E11: about; includes ~$2.25M in grant-funded projects | F11: Board packet | G11: https://nederlandco.civicweb.net/document/126174/
A12: General Fund operating spending, 2026 budget | B12: 3236824 | F12: Board packet | G12: https://nederlandco.civicweb.net/document/126178/
A13: Boulder County Sheriff contract (largest General Fund cost) | B13: 1050000 | E13: about, per year | F13: Board packet | G13: https://nederlandco.civicweb.net/document/116150/
A14: General Fund capital spending | B14: 200000 | E14: $160,000–$200,000 a year | F14: Board packet | G14: https://nederlandco.civicweb.net/document/126178/

Sheet Board votes
A1: Date | B1: Category | C1: Description | D1: Outcome | E1: Vote | F1: Mover | G1: Seconder | H1: Absent | I1: Minutes page | J1: Source URL | K1: Motion text
A2: 45538 | B2: Executive session | C2: Executive session: purchase of property and operations for recreational activities (C.R.S. 24-6-402(4) a, b, e) | D2: approved | E2: Unanimous of those present (7: Giblin, Sterling, Larsen, Maris, Miller, Tye, Corvalan) | F2: Giblin | G2: Sterling | I2: 1 | J2: https://nederlandco.civicweb.net/document/115749/ | K2: to go into executive session pursuant to CRS Sec. 24-6-402(4)(a), (4)(b), and (4)(e)(1) for consideration of the Town’s purchase of property for recreational activities and other municipal services, to receive legal advice, and to instruct negotiators regarding the same
A3: 45586 | B3: Executive session | C3: Executive session: purchase of property and operations for recreational activities (C.R.S. 24-6-402(4) a, b, e) | D3: approved | E3: Unanimous of those present (7: Giblin, Sterling, Corvalan, Miller, Maris, Larsen, Tye) | F3: Giblin | G3: Tye | I3: 1 | J3: https://nederlandco.civicweb.net/document/117285/ | K3: to go into an Executive session pursuant to C.R.S. section 24-6-402(4)(a), (4)(b), and (4)(e)(roman numeral |) for consideration of the Town's purchase of property for recreational activities and other municipal services, to receive legal advice, and to instruct negotiators regarding the same. And an executive Session pursuant to C.R.S. section 24-6-402(4)(b) and (4)(e)( roman numeral |) to receive legal advice and to consider and determine positions related to the contract for water attorney services
A4: 45615 | B4: Executive session | C4: Executive session: purchase of property and operations for recreational activities (C.R.S. 24-6-402(4) a, b, e) | D4: approved | E4: Unanimous of those present (7: Sterling, Maris, Miller, Tye, Giblin, Larsen, Corvalan) | F4: Giblin | G4: Miller | I4: 1 | J4: https://nederlandco.civicweb.net/document/118154/ | K4: to go into executive session pursuant to C.R.S. section 24-6-402(4)(a), (4)(b), and (4)(e)(I) for consideration of the Town’s purchase of property for recreational activities and other municipal services, to receive legal advice, and to instruct negotiators regarding the same
A5: 45629 | B5: Executive session | C5: Executive session: purchase of property and operations for recreational activities (C.R.S. 24-6-402(4) a, b, e) | D5: approved | E5: Unanimous of those present (5: Sterling, Maris, Larsen, Tye, Corvalan); absent: Giblin, Miller | F5: Larsen | G5: Tye | H5: Giblin; Miller | I5: 1 | J5: https://nederlandco.civicweb.net/document/118183/ | K5: to enter into executive session pursuant to C.R.S. section 24-6-402(4)(a), (4)(b), and (4)(e)(I) for consideration of the Town’s purchase of property for recreational activities and other municipal services, to receive legal advice, and to instruct negotiators regarding the same
A6: 45664 | B6: Executive session | C6: Executive session: purchase of property and operations for recreational activities (C.R.S. 24-6-402(4) a, b, e) | D6: approved | E6: Unanimous of those present (7: Sterling, Miller, Larsen, Tye, Giblin, Maris, Corvalan) | F6: Giblin | G6: Sterling | I6: 1 | J6: https://nederlandco.civicweb.net/document/118541/ | K6: to enter into executive session pursuant to C.R.S. section 24-6-402(4)(a), (4)(b), and (4)(e)(I) for consideration of and discussion of the Town's purchase of property for recreational activities and other municipal services to receive legal advice, and to instruct negotiators regarding the same
A7: 45664 | B7: Consent | C7: Ratified retention of Northland Securities as underwriter for possible revenue-bond financing of an Eldora purchase (Res. 2025-02); Letter of Interest to Great Outdoors Colorado for a grant to support the acquisition | D7: approved | E7: Unanimous of those present (7: Giblin, Sterling, Miller, Larsen, Tye, Corvalan, Maris) | F7: Larsen | G7: Tye | I7: 2 | J7: https://nederlandco.civicweb.net/document/118545/ | K7: to approve the Consent Agenda
A8: 45664 | B8: Action | C8: Res. 2025-03: delegated authority to the Town Administrator to engage special legal counsel to evaluate purchasing Eldora Mountain Resort | D8: approved | E8: Unanimous of those present (7: Giblin, Sterling, Miller, Larsen, Tye, Corvalan, Maris) | F8: Miller | G8: Larsen | I8: 2 | J8: https://nederlandco.civicweb.net/document/118545/ | K8: to approve Resolution 2025-03 delegating authority to the Town Administrator to engage special legal counsel
A9: 45672 | B9: Executive session | C9: Executive session: purchase of property and operations for recreational activities (C.R.S. 24-6-402(4) a, b, e) | D9: approved | E9: Unanimous of those present (4: Giblin, Maris, Miller, Tye); absent: Sterling, Corvalan, Larsen | F9: Giblin | G9: Tye | H9: Sterling; Corvalan; Larsen | I9: 1 | J9: https://nederlandco.civicweb.net/document/118536/ | K9: to enter into executive session pursuant to C.R.S. section 24-6-402(4)(a), (4)(b), and (4)(e)(I) for consideration of and discussion of the Town’s purchase of property for recreational activities and other municipal services to receive legal advice, and to instruct negotiators regarding the same
A10: 45678 | B10: Action | C10: Ord. 873 (emergency): established the Mountain Recreation Enterprise Fund "to support the Town's strategic efforts regarding the potential acquisition and operation of the Eldora Ski Area" | D10: approved | E10: Unanimous of those present (7: Giblin, Maris, Miller, Tye, Sterling, Corvalan, Larsen) [roll call: Mayor Pro Tem Sterling left the meeting at 8:04 pm.] | F10: Sterling | G10: Giblin | I10: 3 | J10: https://nederlandco.civicweb.net/document/119617/ | K10: to approve Ordinance 873, the emergency ordinance establishing an enterprise fund for ski recreation, as presented, to support the Town’s strategic efforts regarding the potential acquisition and operation of the Eldora Ski Area
A11: 45734 | B11: Related | C11: Executive session on water-court matters, including Eldora's Application for Conditional Storage Rights (Case No. 23CW3176) and Nederland's Statement of Opposition | D11: approved | E11: Unanimous of those present (5: Sterling, Larsen, Tye, Giblin, Corvalan); absent: Maris, Miller | F11: Giblin | G11: Tye | H11: Maris; Miller | I11: 1 | J11: https://nederlandco.civicweb.net/document/120416/ | K11: to enter into executive session pursuant to C.R.S. § 24-6-402 (4)(b), and (4)(e)(I) to receive legal advice and to instruct negotiators regarding Nederland’s Application for Reasonable Diligence, Water Court Case Nos. 24CW3021, Eldora’s Application for Conditional Storage Rights, Water Court Case No. 23CW3176 and Nederland’s Statement of Opposition in that matter, and continued development of Nederland’s water rights
A12: 45740 | B12: Executive session | C12: Executive session: purchase of property and operations for recreational activities (C.R.S. 24-6-402(4) a, b, e) | D12: approved | E12: Unanimous of those present (7: Giblin, Sterling, Corvalan, Maris, Miller, Larsen, Tye) | F12: Giblin | G12: Tye | I12: 1 | J12: https://nederlandco.civicweb.net/document/120420/ | K12: to enter into executive session pursuant to C.R.S. section 24-6-402(4)(a), (4)(b), and (4)(e)(I) for consideration of and discussion of the Town's purchase of property for recreational activities and other municipal services, to receive legal advice, and to instruct negotiators regarding the same
A13: 45762 | B13: Executive session | C13: Executive session: purchase of property and operations for recreational activities (C.R.S. 24-6-402(4) a, b, e) | D13: approved | E13: Unanimous of those present (6: Giblin, Sterling, Miller, Maris, Tye, Corvalan); absent: Larsen [roll call: Trustee Corvalan joined the meeting at 6:03 pm.] | F13: Giblin | G13: Tye | H13: Larsen | I13: 1 | J13: https://nederlandco.civicweb.net/document/121533/ | K13: to enter into executive session pursuant to C.R.S. section 24-6-402(4)(a), (4)(b), and (4)(e)(I) for consideration of and discussion of the Town’s purchase of property and operations for recreational activities and other municipal services, to receive legal advice, and to instruct negotiators regarding the same
A14: 45762 | B14: Consent | C14: Res. 2025-08: ratified a non-binding Letter of Intent with J.P. Morgan Securities as potential underwriter of revenue bonds for an Eldora acquisition | D14: approved | E14: Unanimous of those present (6: Giblin, Sterling, Miller, Maris, Tye, Corvalan); absent: Larsen | F14: Sterling | G14: Maris | H14: Larsen | I14: 1 | J14: https://nederlandco.civicweb.net/document/121537/ | K14: to approve the Consent Agenda
A15: 45776 | B15: Executive session | C15: Executive session: purchase of property and operations for recreational activities (C.R.S. 24-6-402(4) f, a, b, e); also: Town Administrator/Manager personnel matter | D15: approved | E15: Unanimous of those present (7: Giblin, Sterling, Maris, Miller, Tye, Larsen, Corvalan) [roll call: Trustee Larsen joined the meeting at 6:04 pm. Trustee Corvalan joined the meeting at 7:03 pm. Trustee Maris left the meeting at 7:56 pm.] | F15: Giblin | G15: Tye | I15: 1 | J15: https://nederlandco.civicweb.net/document/121529/ | K15: to enter into executive session pursuant C.R.S. section 24-6-402(4)(f)(I) for a discussion of a personnel matter involving evaluation of the Town Administrator. The Town Administrator has consented to the executive session; and to enter into Executive Session pursuant to C.R.S. section 24-6-402(4)(a), (4)(b), and (4)(e)(I) for consideration of and discussion of the Town’s purchase of property and operations for recreational activities and other municipal services, to receive legal advice, and to instruct negotiators regarding the same
A16: 45797 | B16: Executive session | C16: Executive session: purchase of property and operations for recreational activities (C.R.S. 24-6-402(4) a, b, e) | D16: approved | E16: Unanimous of those present (7: Giblin, Sterling, Miller, Maris, Tye, Corvalan, Larsen) | F16: Giblin | G16: Tye | I16: 1 | J16: https://nederlandco.civicweb.net/document/123026/ | K16: to enter into executive session pursuant to C.R.S. section 24-6-402(4)(a), (4)(b), and (4)(e)(I) for consideration of and discussion of the Town’s purchase of property and operations for recreational activities and other municipal services, to receive legal advice, and to instruct negotiators regarding the same
A17: 45797 | B17: Consent | C17: Res. 2025-11: delegated authority to the Town Administrator to retain additional underwriters and financial advisors for the possible purchase | D17: approved | E17: Unanimous of those present (6: Giblin, Sterling, Maris, Tye, Corvalan, Larsen); absent: Miller | F17: Sterling | G17: Maris | H17: Miller | I17: 1 | J17: https://nederlandco.civicweb.net/document/123034/ | K17: to approve the Consent Agenda
A18: 45853 | B18: Consent | C18: Res. 2025-15: due-diligence agreement with SE Group (financial, operational, and infrastructure review of Eldora). Also approved, as a separate consent item: engagement of Dickinson Wright PLLC for water-rights due diligence on the acquisition | D18: approved | E18: Unanimous of those present (5: Giblin, Larsen, Maris, Miller, Corvalan); absent: Sterling, Tye | F18: Larsen | G18: Miller | H18: Sterling; Tye | I18: 1 | J18: https://nederlandco.civicweb.net/document/124161/ | K18: to approve the Consent Agenda
A19: 45874 | B19: Consent | C19: Res. 2025-16: authorized the Town Manager to engage legal counsel for the acquisition, naming Kline Alvarado Veio as bond counsel (staff memo notes the Town had entered a non-binding term sheet) | D19: approved | E19: Unanimous of those present (7: Sterling, Maris, Miller, Tye, Larsen, Giblin, Corvalan) | F19: Miller | G19: Tye | I19: 1 | J19: https://nederlandco.civicweb.net/document/124165/ | K19: to approve the Consent Agenda
A20: 45874 | B20: Action | C20: Res. 2025-17: declared the Town's official intent to reimburse Eldora project expenditures from a future bond issue | D20: approved | E20: Unanimous of those present (7: Sterling, Maris, Miller, Tye, Larsen, Giblin, Corvalan) | F20: Maris | G20: Miller | I20: 2 | J20: https://nederlandco.civicweb.net/document/124165/ | K20: to approve Resolution 2025-17 a resolution declaring the Town’s official intent to reimburse certain Project-related expenditures from a future bond issuance
A21: 45888 | B21: Executive session | C21: Executive session: purchase of property and operations for recreational activities (C.R.S. 24-6-402(4) a, b, e) | D21: approved | E21: Unanimous of those present (7: Maris, Miller, Larsen, Tye, Giblin, Sterling, Corvalan) | F21: Giblin | G21: Tye | I21: 1 | J21: https://nederlandco.civicweb.net/document/125531/ | K21: to enter into executive session pursuant to C.R.S. section 24-6-402(4)(a), (4)(b), and (4)(e)(I) for consideration of and discussion of the Town's purchase of property for recreational activities and other municipal services, to receive legal advice, and to instruct negotiators regarding the same
A22: 45902 | B22: Executive session | C22: Executive session: purchase of property and operations for recreational activities (C.R.S. 24-6-402(4) a, b, e) | D22: approved | E22: Unanimous of those present (6: Sterling, Miller, Tye, Giblin, Corvalan, Maris); absent: Larsen [roll call: Trustee Maris joined the meeting at 6:06 pm.] | F22: Giblin | G22: Miller | H22: Larsen | I22: 1 | J22: https://nederlandco.civicweb.net/document/125963/ | K22: to enter into executive session pursuant to C.R.S. section 24-6-402(4)(a), (4)(b), and (4)(e)(I) for consideration of and discussion of the Town's purchase of property for recreational activities and other municipal services, to receive legal advice, and to instruct negotiators regarding the same
A23: 45902 | B23: Consent | C23: Res. 2025-19: ratified retention of third-party consultants for due diligence on the Eldora acquisition | D23: approved | E23: Unanimous of those present (6: Giblin, Sterling, Maris, Miller, Tye, Corvalan); absent: Larsen | F23: Miller | G23: Tye | H23: Larsen | I23: 1 | J23: https://nederlandco.civicweb.net/document/125967/ | K23: to approve the Consent Agenda
A24: 45930 | B24: Executive session | C24: Executive session: purchase of property and operations for recreational activities (C.R.S. 24-6-402(4) a, b, e) | D24: approved | E24: Unanimous of those present (5: Sterling, Larsen, Maris, Corvalan, Miller); absent: Tye [roll call: Trustee Miller joined the meeting at 5:34 pm.] | F24: Sterling | G24: Larsen | H24: Tye | I24: 1 | J24: https://nederlandco.civicweb.net/document/125543/ | K24: to enter into executive session pursuant to C.R.S. section 24-6-402(4)(a), (4)(b), and (4)(e)(I) for consideration of and discussion of the Town's purchase of property for recreational activities and other municipal services, to receive legal advice, and to instruct negotiators regarding the same
A25: 45937 | B25: Executive session | C25: Executive session: purchase of property and operations for recreational activities (C.R.S. 24-6-402(4) b, c, e); confidential commercial information | D25: approved | E25: Unanimous of those present (6: Giblin, Sterling, Miller, Tye, Corvalan, Maris); absent: Larsen [roll call: Trustee Maris joined the meeting at 6:09 pm.] | F25: Giblin | G25: Tye | H25: Larsen | I25: 1 | J25: https://nederlandco.civicweb.net/document/126577/ | K25: to enter into executive session pursuant to C.R.S. section 24-6-402(4}(a), (4)(b), (4)(c), and (4)(e)(I) for consideration of matters required to be kept confidential by Colorado law, C.R.S. section 24-72- 204(3)(a)(IV) regarding protection of confidential commercial information, and discussion of the Town’s purchase of property and operations for recreational activities and other municipal services, to receive legal advice, and to instruct negotiators regarding the same
A26: 45937 | B26: Consent | C26: Res. 2025-22: ratified retention of contractors and consultants (HR, finance, and accounting and forecasting) related to the acquisition | D26: approved | E26: Unanimous of those present (6: Giblin, Sterling, Maris, Larsen, Tye, Corvalan); absent: Miller | F26: Larsen | G26: Maris | H26: Miller | I26: 1 | J26: https://nederlandco.civicweb.net/document/126581/ | K26: to approve the Consent Agenda except for item 3.5 Rescheduling the November 4, 2025 Regular BOT Meeting
A27: 45951 | B27: Executive session | C27: Executive session: purchase of property and operations for recreational activities (C.R.S. 24-6-402(4) a, b, c, e); confidential commercial information | D27: approved | E27: Unanimous of those present (4: Giblin, Miller, Maris, Sterling); absent: Tye, Larsen, Corvalan | F27: Giblin | G27: Miller | H27: Tye; Larsen; Corvalan | I27: 1 | J27: https://nederlandco.civicweb.net/document/125515/ | K27: to enter into executive session pursuant to C.R.S. section 24-6-402(4)(a), (4)(b), (4)(c), and (4)(e)(I) for consideration of matters required to be kept confidential by Colorado law, C.R.S. section 24-72- 204(3)(a)(IV) regarding protection of confidential commercial information, and discussion of the Town’s purchase of property and operations for recreational activities and other municipal services, to receive legal advice, and to instruct negotiators regarding the same
A28: 45960 | B28: Executive session | C28: Executive session: purchase of property and operations for recreational activities (C.R.S. 24-6-402(4) a, b, c, e); confidential commercial information | D28: approved | E28: Unanimous of those present (5: Giblin, Sterling, Miller, Maris, Corvalan); absent: Tye, Larsen [roll call: Trustee Corvalan joined the meeting at 6:09 pm.] | F28: Giblin | G28: Miller | H28: Tye; Larsen | I28: 1 | J28: https://nederlandco.civicweb.net/document/125516/ | K28: to enter into executive session pursuant to C.R.S. section 24-6-402(4)(a), (4)(b), (4)(c), and (4)(e)(I) for consideration of matters required to be kept confidential by Colorado law, C.R.S. section 24-72- 204(3)(a)(IV) regarding protection of confidential commercial information, and discussion of the Town’s purchase of property and operations for recreational activities and other municipal services, to receive legal advice, and to instruct negotiators regarding the same
A29: 45966 | B29: Executive session | C29: Executive session: purchase of property and operations for recreational activities (C.R.S. 24-6-402(4) a, b, c, e); confidential commercial information | D29: approved | E29: Unanimous of those present (5: Larsen, Maris, Miller, Corvalan, Giblin); absent: Sterling, Tye | F29: Larsen | G29: Miller | H29: Sterling; Tye | I29: 1 | J29: https://nederlandco.civicweb.net/document/126569/ | K29: to enter into executive session pursuant to C.R.S. section 24-6-402(4)(a), (4)(b), (4)(c), and (4)(e)(I) for consideration of matters required to be kept confidential by Colorado law, C.R.S. section 24-72- 204(3)(a)(!V) regarding protection of confidential commercial information, and discussion of the Town’s purchase of property and operations for recreational activities and other municipal services, to receive legal advice, and to instruct negotiators regarding the same
A30: 45979 | B30: Executive session | C30: Executive session: purchase of property and operations for recreational activities (C.R.S. 24-6-402(4) a, b, c, e); confidential commercial information | D30: approved | E30: Unanimous of those present (6: Sterling, Larsen, Maris, Miller, Giblin, Corvalan) | F30: Giblin | G30: Larsen | I30: 1 | J30: https://nederlandco.civicweb.net/document/126298/ | K30: to enter into executive session pursuant to C.R.S. section 24-6-402(4)(a), (4)(b), (4)(c), and (4)(e)(I) for consideration of matters required to be kept confidential by Colorado law, C.R.S. section 24-72- 204(3)(a)(IV) regarding protection of confidential commercial information, and discussion of the Town’s purchase of property and operations for recreational activities and other municipal services, to receive legal advice, and to instruct negotiators regarding the same
A31: 45993 | B31: Executive session | C31: Executive session: purchase of property and operations for recreational activities (C.R.S. 24-6-402(4) a, b, c, e); confidential commercial information | D31: approved | E31: Unanimous of those present (6: Giblin, Larsen, Maris, Sterling, Corvalan, Miller) [roll call: Trustee Miller joined the meeting virtually at 6:08 pm and left the meeting at 6:52 pm.] | F31: Giblin | G31: Maris | I31: 1 | J31: https://nederlandco.civicweb.net/document/126589/ | K31: to enter into executive session pursuant to C.R.S. section 24-6-402(4)(a), (4)(b), (4)(c), and (4)(e)(I) for consideration of matters required to be kept confidential by Colorado law, C.R.S. section 24-72- 204(3)(a)(IV) regarding protection of confidential commercial information, and discussion of the Town’s purchase of property and operations for recreational activities and other municipal services, to receive legal advice, and to instruct negotiators regarding the same
A32: 46007 | B32: Executive session | C32: Executive session: purchase of property and operations for recreational activities (C.R.S. 24-6-402(4) a, b, c, e); confidential commercial information | D32: approved | E32: Unanimous of those present (6: Sterling, Miller, Maris, Giblin, Larsen, Corvalan) | F32: Giblin | G32: Miller | I32: 1 | J32: https://nederlandco.civicweb.net/document/127827/ | K32: to enter into executive session pursuant to C.R.S. section 24-6-402(4)(a), (4)(b), (4)(c), and (4)(e)(I) for consideration of matters required to be kept confidential by Colorado law, C.R.S. section 24-72- 204(3)(a)(IV) regarding protection of confidential commercial information, and discussion of the Town’s purchase of property and operations for recreational activities and other municipal services, to receive legal advice, and to instruct negotiators regarding the same
A33: 46028 | B33: Executive session | C33: Executive session: purchase of property and operations for recreational activities (C.R.S. 24-6-402(4) a, b, c, e); confidential commercial information | D33: approved | E33: Unanimous of those present (5: Maris, Miller, Joslin, Sterling, Giblin); absent: Corvalan, Larsen | F33: Giblin | G33: Miller | H33: Corvalan; Larsen | I33: 1 | J33: https://nederlandco.civicweb.net/document/127835/ | K33: to enter into executive session pursuant to C.R.S. section 24-6-402(4)(a), (4)(b), (4)(c), and (4)(e)(1) for consideration of matters required to be kept confidential by Colorado law, C.R.S. section 24-72- 204(3)(a)(IV) regarding protection of confidential commercial information, and discussion of the Town’s purchase of property and operations for recreational activities and other municipal services, to receive legal advice, and to instruct negotiators regarding the same
A34: 46028 | B34: Action | C34: Ord. 882: authorized execution of the Asset Purchase Agreement for the acquisition of Eldora Mountain Resort, acting through the Mountain Recreation Enterprise | D34: approved | E34: Unanimous of those present (5: Giblin, Maris, Miller, Joslin, Sterling); absent: Larsen, Corvalan | F34: Sterling | G34: Giblin | H34: Larsen; Corvalan | I34: 2 | J34: https://nederlandco.civicweb.net/document/127841/ | K34: to approve Ordinance 882 an ordinance of the Board of Trustees of the Town of Nederland, Colorado, acting by and through the Mountain Recreation Enterprise, authorizing the execution of an Asset Purchase Agreement and related documents for the acquisition of Eldora Mountain Resort; declaring the public purposes and benefits of such acquisition; and authorizing the Mayor or Mayor Pro Tem to execute the documents necessary to effectuate the transaction
A35: 46042 | B35: Executive session | C35: Executive session: purchase of property and operations for recreational activities (C.R.S. 24-6-402(4) a, b, c, e); confidential commercial information | D35: approved | E35: Unanimous of those present (7: Sterling, Maris, Miller, Joslin, Giblin, Corvalan, Larsen) | F35: Giblin | G35: Miller | I35: 1 | J35: https://nederlandco.civicweb.net/document/127856/ | K35: to enter into executive session pursuant to C.R.S. section 24-6-402(4)(a), (4)(b), (4)(c), and (4)(e)(!) for consideration of matters required to be kept confidential by Colorado law, C.R.S. section 24-72- 204(3)(a)(IV) regarding protection of confidential commercial information, and discussion of the Town’s purchase of property and operations for recreational activities and other municipal services, to receive legal advice, and to instruct negotiators regarding the same
